<?xml version="1.0"?>
<robot name="bravo_finger_jaws" xmlns:xacro="http://ros.org/wiki/xacro">
    <xacro:macro name="bravo_finger_jaws" params="parent *origin name:=bravo_finger_jaws axis_a">
        <material name="${name}_black">
            <color rgba="0.3 0.3 0.3 1" />
        </material>
        <joint name="${name}_joint" type="fixed">
            <xacro:insert_block name="origin" />
            <parent link="${parent}"/>
            <child link="${name}_base_link" />
            <origin xyz="0 0 0" rpy="0 0 0"/>
        </joint>

        <link name="${name}_base_link">
            <visual>
                <geometry>
                    <mesh filename="package://bpl_bravo_description_mk2/meshes/RS2-257.stl"/>
                </geometry>
                <material name="${name}_black"/>
            </visual>
            <collision>
                <geometry>
                    <cylinder radius="0.0355" length="0.037"/>
                </geometry>
                <origin rpy="0 1.5707 0" xyz="0.0123 0 0"/>
            </collision>
        </link>

        <link name="${name}_rs2_300_link">
            <visual>
                <geometry>
                    <mesh filename="package://bpl_bravo_description_mk2/meshes/RS2-300.stl"/>
                </geometry>
                <material name="${name}_black"/>

            </visual>
            <collision>
                <geometry>
                    <box size="0.124 0.035 0.042"/>
                </geometry>
                <origin rpy="0 0 2.78554548618295" xyz="0.0595 -0.0267 0"/>
            </collision>
        </link>

        <joint name="${name}_rs2_300_joint" type="revolute">
            <origin xyz="0.0241 0.0268 0" rpy="0 0 0"/>
            <axis xyz="0 0 1"/>
            <parent link="${name}_base_link"/>
            <child link="${name}_rs2_300_link"/>
            <limit lower="0" upper="1.0" effort="10" velocity="10"/>
            <mimic joint="${axis_a}" multiplier="54" offset="0"/>
        </joint>

        <link name="${name}_rs2_301_link">
            <visual>
                <geometry>
                    <mesh filename="package://bpl_bravo_description_mk2/meshes/RS2-301.stl"/>
                </geometry>
                <material name="${name}_black"/>
            </visual>
            <collision>
                <geometry>
                    <box size="0.124 0.035 0.042"/>
                </geometry>
                <origin rpy="0 0 -2.78554548618295" xyz="0.0595 0.0267 0"/>
            </collision>
        </link>

        <joint name="${name}_rs2_301_joint" type="revolute">
            <origin xyz="0.0241 -0.0268 0" rpy="0 0 0"/>
            <axis xyz="0 0 -1"/>
            <parent link="${name}_base_link"/>
            <child link="${name}_rs2_301_link"/>
            <limit lower="0" upper="1.0" effort="10" velocity="10"/>
            <mimic joint="${name}_rs2_300_joint" multiplier="1" offset="0"/>
        </joint>
    </xacro:macro>
</robot>