<?xml version="1.0" encoding="utf-8"?>
<!-- =================================================================================== -->
<!-- |    This document was autogenerated by xacro from bravo_7_example.urdf.xacro     | -->
<!-- |    EDITING THIS FILE BY HAND IS NOT RECOMMENDED                                 | -->
<!-- =================================================================================== -->
<robot name="bravo_7_example">
  <link name="base_link"/>
  <joint name="bravo_joint" type="fixed">
    <origin rpy="0 0 0" xyz="0 0 0"/>
    <parent link="base_link"/>
    <child link="bravo_base_link"/>
    <origin rpy="0 0 0" xyz="0 0 0"/>
  </joint>
  <material name="bravo_black">
    <color rgba="0.3 0.3 0.3 1"/>
  </material>
  <link name="bravo_base_link">
    <visual>
      <geometry>
        <mesh filename="package://bpl_bravo_description/meshes/RS2-1019_base.stl"/>
      </geometry>
      <material name="bravo_black"/>
    </visual>
    <collision>
      <geometry>
        <box size="0.0725 0.1112 0.083"/>
      </geometry>
      <origin rpy="0 0 0" xyz="0.03625 00 0.0415"/>
    </collision>
    <collision>
      <geometry>
        <box size="0.050 0.080 0.060"/>
      </geometry>
      <origin rpy="0 0 0" xyz="0.025 -0.04556 0.03"/>
    </collision>
    <collision>
      <geometry>
        <cylinder length="0.083" radius="0.046"/>
      </geometry>
      <origin rpy="0 0 0" xyz="0.0665 0 0.0415"/>
    </collision>
  </link>
  <joint name="bravo_axis_g" type="revolute">
    <parent link="bravo_base_link"/>
    <origin rpy="0 0 3.14159" xyz="0.0665 0 0.08"/>
    <axis xyz="0 0 -1"/>
    <child link="bravo_1019_end_link"/>
    <limit effort="0" lower="0.0" upper="6.3" velocity="0"/>
  </joint>
  <link name="bravo_1019_end_link">
    <visual>
      <geometry>
        <mesh filename="package://bpl_bravo_description/meshes/RS2-1019_end.stl"/>
      </geometry>
      <material name="bravo_black"/>
    </visual>
  </link>
  <joint name="bravo_f_base_joint" type="fixed">
    <parent link="bravo_1019_end_link"/>
    <origin rpy="0 0 0" xyz="0 0 0"/>
    <child link="bravo_1013_base_link"/>
  </joint>
  <link name="bravo_1013_base_link">
    <visual>
      <geometry>
        <mesh filename="package://bpl_bravo_description/meshes/RS2-1013_base.stl"/>
      </geometry>
      <material name="bravo_black"/>
    </visual>
    <collision>
      <geometry>
        <cylinder length="0.030" radius="0.046"/>
      </geometry>
      <origin rpy="0 0 0" xyz="0.0 00 0.015"/>
    </collision>
    <collision>
      <geometry>
        <cylinder length="0.1" radius="0.046"/>
      </geometry>
      <origin rpy="1.5707 0 0 " xyz="0.048 00 0.0642"/>
    </collision>
  </link>
  <joint name="bravo_axis_f" type="revolute">
    <parent link="bravo_1013_base_link"/>
    <origin rpy="0 0 0" xyz="0.046 0 0.0642"/>
    <axis xyz="0 -1 0"/>
    <child link="bravo_1013_joint_link"/>
    <limit effort="0" lower="0.0" upper="3.2" velocity="0"/>
  </joint>
  <link name="bravo_1013_joint_link">
    <visual>
      <geometry>
        <mesh filename="package://bpl_bravo_description/meshes/RS2-1013_end.stl"/>
      </geometry>
      <material name="bravo_black"/>
    </visual>
    <collision>
      <geometry>
        <cylinder length="0.03" radius="0.046"/>
      </geometry>
      <origin rpy="0 0 0" xyz="0.046 0 -0.03555"/>
    </collision>
  </link>
  <joint name="bravo_1013_end_joint" type="fixed">
    <parent link="bravo_1013_joint_link"/>
    <origin rpy="3.14159 0 3.14159" xyz="0.046 0 -0.05055"/>
    <child link="bravo_1013_end_link"/>
  </joint>
  <link name="bravo_1013_end_link"/>
  <joint name="bravo_e_base_joint" type="fixed">
    <parent link="bravo_1013_end_link"/>
    <origin rpy="0 0 0" xyz="0 0 0.182"/>
    <child link="bravo_1026_0_base_link"/>
  </joint>
  <link name="bravo_1026_0_base_link">
    <visual>
      <geometry>
        <mesh filename="package://bpl_bravo_description/meshes/RS2-1026_0_base.stl"/>
      </geometry>
      <material name="bravo_black"/>
    </visual>
    <collision>
      <geometry>
        <cylinder length="0.03" radius="0.0408"/>
      </geometry>
      <origin rpy="0 0 0" xyz="0 00 0.015"/>
    </collision>
    <collision>
      <geometry>
        <cylinder length="0.0816" radius="0.0408"/>
      </geometry>
      <origin rpy="1.5707 0 0" xyz="0.0408 00 0.0578"/>
    </collision>
  </link>
  <joint name="bravo_axis_e" type="revolute">
    <parent link="bravo_1026_0_base_link"/>
    <origin rpy="0 0 0" xyz="0.042 0 0.0578"/>
    <axis xyz="0 -1 0"/>
    <child link="bravo_1026_0_joint_link"/>
    <limit effort="0" lower="0.0" upper="3.2" velocity="0"/>
  </joint>
  <link name="bravo_1026_0_joint_link">
    <visual>
      <geometry>
        <mesh filename="package://bpl_bravo_description/meshes/RS2-1026_0_end.stl"/>
      </geometry>
      <material name="bravo_black"/>
    </visual>
    <collision>
      <geometry>
        <cylinder length="0.080" radius="0.0408"/>
      </geometry>
      <origin rpy="0 0 0" xyz="0.0408 0 -0.05385"/>
    </collision>
  </link>
  <joint name="bravo_1026_0_end_joint" type="fixed">
    <parent link="bravo_1026_0_joint_link"/>
    <origin rpy="3.14159 0 0" xyz="0.0408 0 -0.09385"/>
    <child link="bravo_1026_0_end_link"/>
  </joint>
  <link name="bravo_1026_0_end_link"/>
  <joint name="bravo_d_base_joint" type="fixed">
    <parent link="bravo_1026_0_end_link"/>
    <origin rpy="0 0 0" xyz="0 0 0"/>
    <child link="bravo_1026_1_base_link"/>
  </joint>
  <link name="bravo_1026_1_base_link">
        </link>
  <joint name="bravo_axis_d" type="revolute">
    <parent link="bravo_1026_1_base_link"/>
    <origin rpy="0 0 0" xyz="0 0 0.0005"/>
    <axis xyz="0 0 -1"/>
    <child link="bravo_1026_1_joint_link"/>
    <limit effort="0" lower="0" upper="6.2" velocity="0"/>
  </joint>
  <link name="bravo_1026_1_joint_link">
    <visual>
      <geometry>
        <mesh filename="package://bpl_bravo_description/meshes/RS2-1026_1_end.stl"/>
      </geometry>
      <material name="bravo_black"/>
      <origin rpy="0 0 3.14159" xyz="0 0 0 "/>
    </visual>
    <collision>
      <geometry>
        <cylinder length="0.0056" radius="0.0408"/>
      </geometry>
      <origin rpy="0 0 3.14159" xyz="0 0 0.0028"/>
    </collision>
  </link>
  <joint name="bravo_1026_1_end_joint" type="fixed">
    <parent link="bravo_1026_1_joint_link"/>
    <origin rpy="0 0 3.14159" xyz="0 0 0.0056"/>
    <child link="bravo_1026_1_end_link"/>
  </joint>
  <link name="bravo_1026_1_end_link"/>
  <joint name="bravo_c_base_joint" type="fixed">
    <parent link="bravo_1026_1_end_link"/>
    <origin rpy="0 0 0" xyz="0 0 0.0"/>
    <child link="bravo_1023_0_base_link"/>
  </joint>
  <link name="bravo_1023_0_base_link">
    <visual>
      <geometry>
        <mesh filename="package://bpl_bravo_description/meshes/RS2-1023_0_base.stl"/>
      </geometry>
      <material name="bravo_black"/>
    </visual>
    <collision>
      <geometry>
        <cylinder length="0.03" radius="0.0408"/>
      </geometry>
      <origin rpy="0 0 0" xyz="0 00 0.015"/>
    </collision>
    <collision>
      <geometry>
        <cylinder length="0.0816" radius="0.0408"/>
      </geometry>
      <origin rpy="1.5707 0 0" xyz="0.0408 00 0.0578"/>
    </collision>
  </link>
  <joint name="bravo_axis_c" type="revolute">
    <parent link="bravo_1023_0_base_link"/>
    <origin rpy="0 0 0" xyz="0.042 0 0.0578"/>
    <axis xyz="0 -1 0"/>
    <child link="bravo_1023_0_joint_link"/>
    <limit effort="0" lower="0.0" upper="3.2" velocity="0"/>
  </joint>
  <link name="bravo_1023_0_joint_link">
    <visual>
      <geometry>
        <mesh filename="package://bpl_bravo_description/meshes/RS2-1023_0_end.stl"/>
      </geometry>
      <material name="bravo_black"/>
    </visual>
    <collision>
      <geometry>
        <cylinder length="0.080" radius="0.0408"/>
      </geometry>
      <origin rpy="0 0 0" xyz="0.0408 0 -0.05385"/>
    </collision>
  </link>
  <joint name="bravo_1023_0_end_joint" type="fixed">
    <parent link="bravo_1023_0_joint_link"/>
    <origin rpy="3.14159 0 0" xyz="0.0408 0 -0.09385"/>
    <child link="bravo_1023_0_end_link"/>
  </joint>
  <link name="bravo_1023_0_end_link"/>
  <joint name="bravo_b_base_joint" type="fixed">
    <parent link="bravo_1023_0_end_link"/>
    <origin rpy="0 0 0" xyz="0 0 0"/>
    <child link="bravo_1023_1_base_link"/>
  </joint>
  <link name="bravo_1023_1_base_link">
        </link>
  <joint name="bravo_axis_b" type="continuous">
    <parent link="bravo_1023_1_base_link"/>
    <origin rpy="0 0 0" xyz="0 0 0.0005"/>
    <axis xyz="0 0 -1"/>
    <child link="bravo_1023_1_joint_link"/>
    <!--            <limit effort="0" velocity="0" lower="0.0" upper="0.0" />-->
  </joint>
  <link name="bravo_1023_1_joint_link">
    <visual>
      <geometry>
        <mesh filename="package://bpl_bravo_description/meshes/RS2-1023_1_end.stl"/>
      </geometry>
      <material name="bravo_black"/>
    </visual>
    <collision>
      <geometry>
        <cylinder length="0.0056" radius="0.0408"/>
      </geometry>
      <origin rpy="0 0 0" xyz="0 0 0.0028"/>
    </collision>
  </link>
  <joint name="bravo_1023_1_end_joint" type="fixed">
    <parent link="bravo_1023_1_joint_link"/>
    <origin rpy="0 0 0" xyz="0 0 0.0056"/>
    <child link="bravo_1023_1_end_link"/>
  </joint>
  <link name="bravo_1023_1_end_link"/>
  <joint name="bravo_a_base_joint" type="fixed">
    <parent link="bravo_1023_1_end_link"/>
    <origin rpy="0 0 0" xyz="0 0 0"/>
    <child link="bravo_1028_base_link"/>
  </joint>
  <link name="bravo_1028_base_link">
    <visual>
      <geometry>
        <mesh filename="package://bpl_bravo_description/meshes/RS2-1028.stl"/>
      </geometry>
      <material name="bravo_black"/>
    </visual>
    <collision>
      <geometry>
        <cylinder length="0.120" radius="0.0408"/>
      </geometry>
      <origin rpy="0 0 0" xyz="0 0 0.06"/>
    </collision>
  </link>
  <joint name="bravo_1028_end_joint" type="fixed">
    <parent link="bravo_1028_base_link"/>
    <origin rpy="-1.5707 -1.5707 0" xyz="0 0 0.120"/>
    <child link="bravo_1028_end_link"/>
  </joint>
  <link name="bravo_1028_end_link"/>
  <joint name="bravo_jaws_joint" type="fixed">
    <origin rpy="0 0 0" xyz=" 0 0 0.0"/>
    <parent link="bravo_1028_end_link"/>
    <child link="bravo_jaws_base_link"/>
  </joint>
  <link name="bravo_jaws_base_link">
    <!--        <visual>-->
    <!--            <geometry>-->
    <!--                <mesh filename="package://bpl_bravo_description/meshes/end_effectors/RS2-257.stl"/>-->
    <!--            </geometry>-->
    <!--            <material name="bravo_jaws_black"/>-->
    <!--            </visual>-->
  </link>
  <link name="bravo_push_rod"/>
  <joint name="bravo_axis_a" type="prismatic">
    <origin rpy="0 0 0" xyz="0 0 0.009"/>
    <parent link="bravo_jaws_base_link"/>
    <child link="bravo_push_rod"/>
    <axis xyz="0 0 1"/>
    <limit effort="10" lower="0" upper="0.035" velocity="10"/>
  </joint>
  <link name="bravo_1030_base_link">
    <visual>
      <geometry>
        <mesh filename="package://bpl_bravo_description/meshes/RS2-1030.stl"/>
      </geometry>
      <material name="bravo_black"/>
    </visual>
    <collision>
      <geometry>
        <cylinder length="0.03033333" radius="0.046"/>
      </geometry>
      <origin rpy="0 0 0" xyz="0 0 0.01516666"/>
    </collision>
    <collision>
      <geometry>
        <cylinder length="0.03033333" radius="0.045"/>
      </geometry>
      <origin rpy="0 0 0" xyz="0 0 0.0455"/>
    </collision>
    <collision>
      <geometry>
        <cylinder length="0.03033333" radius="0.044"/>
      </geometry>
      <origin rpy="0 0 0" xyz="0 0 0.075833333"/>
    </collision>
    <collision>
      <geometry>
        <cylinder length="0.03033333" radius="0.043"/>
      </geometry>
      <origin rpy="0 0 0" xyz="0 0 0.1061666666"/>
    </collision>
    <collision>
      <geometry>
        <cylinder length="0.03033333" radius="0.042"/>
      </geometry>
      <origin rpy="0 0 0" xyz="0 0 0.1365"/>
    </collision>
    <collision>
      <geometry>
        <cylinder length="0.03033333" radius="0.041"/>
      </geometry>
      <origin rpy="0 0 0" xyz="0 0 0.1668333"/>
    </collision>
  </link>
  <joint name="bravo_1030_base_joint" type="fixed">
    <parent link="bravo_1013_end_link"/>
    <child link="bravo_1030_base_link"/>
    <origin rpy="0 0 0" xyz="0 0 0"/>
  </joint>
  <material name="bravo_finger_jaws_black">
    <color rgba="0.3 0.3 0.3 1"/>
  </material>
  <joint name="bravo_finger_jaws_joint" type="fixed">
    <origin rpy="0 0 0" xyz="0 0 0"/>
    <parent link="bravo_jaws_base_link"/>
    <child link="bravo_finger_jaws_base_link"/>
    <origin rpy="0 0 0" xyz="0 0 0"/>
  </joint>
  <link name="bravo_finger_jaws_base_link">
    <visual>
      <geometry>
        <mesh filename="package://bpl_bravo_description/meshes/end_effectors/RS2-257.stl"/>
      </geometry>
      <material name="bravo_finger_jaws_black"/>
    </visual>
    <collision>
      <geometry>
        <cylinder length="0.02" radius="0.05"/>
      </geometry>
      <origin rpy="0 1.5707 0" xyz="0.01 0 0.00"/>
    </collision>
  </link>
  <link name="bravo_finger_jaws_rs2_300_link">
    <visual>
      <geometry>
        <mesh filename="package://bpl_bravo_description/meshes/end_effectors/RS2-300.stl"/>
      </geometry>
      <material name="bravo_finger_jaws_black"/>
    </visual>
    <collision>
      <geometry>
        <box size="0.14 0.04 0.045"/>
      </geometry>
      <origin rpy="0 0 0.35" xyz="0.07 0.025 0.00"/>
    </collision>
  </link>
  <joint name="bravo_finger_jaws_rs2_300_joint" type="revolute">
    <origin rpy="0 0 0" xyz="0.0097 -0.033 0"/>
    <parent link="bravo_finger_jaws_base_link"/>
    <child link="bravo_finger_jaws_rs2_300_link"/>
    <axis xyz="0 0 -1"/>
    <limit effort="10" lower="0" upper="1.0" velocity="10"/>
    <mimic joint="bravo_axis_a" multiplier="18" offset="0"/>
  </joint>
  <link name="bravo_finger_jaws_rs2_301_link">
    <visual>
      <geometry>
        <mesh filename="package://bpl_bravo_description/meshes/end_effectors/RS2-301.stl"/>
      </geometry>
      <material name="bravo_finger_jaws_black"/>
    </visual>
    <collision>
      <geometry>
        <box size="0.14 0.04 0.045"/>
      </geometry>
      <origin rpy="0 0 -0.35" xyz="0.07 -0.025 0.00"/>
    </collision>
  </link>
  <joint name="bravo_finger_jaws_rs2_301_joint" type="revolute">
    <origin rpy="0 0 0" xyz="0.0097 0.033 0"/>
    <parent link="bravo_finger_jaws_base_link"/>
    <child link="bravo_finger_jaws_rs2_301_link"/>
    <axis xyz="0 0 1"/>
    <limit effort="10" lower="0" upper="1.0" velocity="10"/>
    <mimic joint="bravo_finger_jaws_rs2_300_joint" multiplier="1" offset="0"/>
  </joint>
</robot>

