<?xml version="1.0"?>
<robot name="bravo_5" xmlns:xacro="http://ros.org/wiki/xacro">


    <xacro:macro name="bravo_5" params="parent *origin  name:=bravo_5">
         <joint name="${name}_joint" type="fixed">
            <xacro:insert_block name="origin" />
            <parent link="${parent}"/>
            <child link="${name}_base_link" />
            <origin xyz="0 0 0" rpy="0 0 0"/>
        </joint>
        <material name="${name}_black">
            <color rgba="0.3 0.3 0.3 1"/>
        </material>
        <link name="${name}_base_link">
            <visual>
                <geometry>
                    <mesh filename="package://bpl_bravo_description/meshes/RS2-1019_base.stl"/>
                </geometry>
                <material name="${name}_black"/>
            </visual>
           <collision>
            <geometry>
                <box size="0.0725 0.1112 0.083"/>
            </geometry>
            <origin rpy="0 0 0" xyz="0.03625 00 0.0415"/>
        </collision>

        <collision>
            <geometry>
                <box size="0.050 0.080 0.060"/>
            </geometry>
            <origin rpy="0 0 0" xyz="0.025 -0.04556 0.03"/>
        </collision>

        <collision>
            <geometry>
                <cylinder radius="0.046" length="0.083"/>
            </geometry>
            <origin rpy="0 0 0" xyz="0.0665 0 0.0415"/>
        </collision>

        </link>
        
        <joint name="${name}_axis_e" type="revolute">
            <parent link="${name}_base_link"/>
            <origin xyz="0.0665 0 0.08" rpy="0 0 3.14159"/>
            <axis xyz="0 0 -1"/>
            <child link="${name}_1019_end_link"/>
            <limit effort="0" velocity="0" lower="0.0" upper="6.3" />
        </joint>

        <link name="${name}_1019_end_link">
            <visual>
                <geometry>
                    <mesh filename="package://bpl_bravo_description/meshes/RS2-1019_end.stl"/>
                </geometry>
                <material name="${name}_black"/>
            </visual>
        </link>
        
            
        <joint name="${name}_d_base_joint" type="fixed">
            <parent link="${name}_1019_end_link"/>
            <origin xyz="0 0 0" rpy="0 0 0"/>
            <child link="${name}_1013_base_link"/>
        </joint>
    
        <link name="${name}_1013_base_link">
            <visual>
                <geometry>
                    <mesh filename="package://bpl_bravo_description/meshes/RS2-1013_base.stl"/>
                </geometry>
                <material name="${name}_black"/>
            </visual>
            <collision>
                <geometry>
                    <cylinder radius="0.046" length="0.030"/>
                </geometry>
                <origin rpy="0 0 0" xyz="0.0 00 0.015"/>
            </collision>
    
            <collision>
                <geometry>
                    <cylinder radius="0.046" length="0.1"/>
                </geometry>
                <origin rpy="1.5707 0 0 " xyz="0.048 00 0.0642"/>
            </collision>
        </link>
    
        <joint name="${name}_axis_d" type="revolute">
            <parent link="${name}_1013_base_link"/>
            <origin xyz="0.046 0 0.0642" rpy="0 0 0"/>
            <axis xyz="0 -1 0"/>
            <child link="${name}_1013_joint_link"/>
            <limit effort="0" velocity="0" lower="0.0" upper="3.2" />
        </joint>
    
    
        <link name="${name}_1013_joint_link">
            <visual>
                <geometry>
                    <mesh filename="package://bpl_bravo_description/meshes/RS2-1013_end.stl"/>
                </geometry>
                <material name="${name}_black"/>
            </visual>
    
            <collision>
    
                <geometry>
                    <cylinder radius="0.046" length="0.03"/>
                </geometry>
                <origin rpy="0 0 0" xyz="0.046 0 -0.03555"/>
            </collision>
        </link>
    
        <joint name="${name}_1013_end_joint" type="fixed">
            <parent link="${name}_1013_joint_link"/>
            <origin xyz="0.046 0 -0.05055" rpy="3.14159 0 3.14159"/>
            <child link="${name}_1013_end_link"/>
        </joint>
    
        <link name="${name}_1013_end_link"/>
    


    
        <joint name="${name}_c_base_joint" type="fixed">
            <parent link="${name}_1013_end_link"/>
            <origin xyz="0 0 0.182" rpy="0 0 0"/>
            <child link="${name}_1023_0_base_link"/>
        </joint>
    
    
        <link name="${name}_1023_0_base_link">
            <visual>
                <geometry>
                    <mesh filename="package://bpl_bravo_description/meshes/RS2-1023_0_base.stl"/>
                </geometry>
                <material name="${name}_black"/>
            </visual>
            <collision>
                <geometry>
                    <cylinder radius="0.0408" length="0.03" />
                </geometry>
                <origin rpy="0 0 0" xyz="0 00 0.015"/>
            </collision>
    
            <collision>
                <geometry>
                    <cylinder radius="0.0408" length="0.0816" />
                </geometry>
                <origin rpy="1.5707 0 0" xyz="0.0408 00 0.0578"/>
            </collision>
    
        </link>
    
        <joint name="${name}_axis_c" type="revolute">
            <parent link="${name}_1023_0_base_link"/>
            <origin xyz="0.042 0 0.0578" rpy="0 0 0"/>
            <axis xyz="0 -1 0"/>
            <child link="${name}_1023_0_joint_link"/>
            <limit effort="0" velocity="0" lower="0.0" upper="3.2" />
        </joint>
    
        <link name="${name}_1023_0_joint_link">
            <visual>
                <geometry>
                    <mesh filename="package://bpl_bravo_description/meshes/RS2-1023_0_end.stl"/>
                </geometry>
                <material name="${name}_black"/>
            </visual>
            <collision>
                <geometry>
                    <cylinder radius="0.0408" length="0.080"/>
                </geometry>
                <origin rpy="0 0 0" xyz="0.0408 0 -0.05385"/>
            </collision>
        </link>
    
        <joint name="${name}_1023_0_end_joint" type="fixed">
            <parent link="${name}_1023_0_joint_link"/>
            <origin xyz="0.0408 0 -0.09385" rpy="3.14159 0 0"/>
            <child link="${name}_1023_0_end_link"/>
        </joint>
    
        <link name="${name}_1023_0_end_link"/>
    
        <joint name="${name}_b_base_joint" type="fixed">
            <parent link="${name}_1023_0_end_link"/>
            <origin xyz="0 0 0" rpy="0 0 0"/>
            <child link="${name}_1023_1_base_link"/>
        </joint>
    
    
        <link name="${name}_1023_1_base_link">
        </link>
    
        <joint name="${name}_axis_b" type="continuous">
            <parent link="${name}_1023_1_base_link"/>
            <origin xyz="0 0 0.0005" rpy="0 0 0"/>
            <axis xyz="0 0 -1"/>
            <child link="${name}_1023_1_joint_link"/>
<!--            <limit effort="0" velocity="0" lower="0.0" upper="0.0" />-->
        </joint>
    
        <link name="${name}_1023_1_joint_link">
            <visual>
                <geometry>
                    <mesh filename="package://bpl_bravo_description/meshes/RS2-1023_1_end.stl"/>
                </geometry>
                <material name="${name}_black"/>
            </visual>
            <collision>
                <geometry>
                    <cylinder radius="0.0408" length="0.0056"/>
                </geometry>
                <origin rpy="0 0 0" xyz="0 0 0.0028"/>
            </collision>
        </link>
    
        <joint name="${name}_1023_1_end_joint" type="fixed">
            <parent link="${name}_1023_1_joint_link"/>
            <origin xyz="0 0 0.0056" rpy="0 0 0"/>
            <child link="${name}_1023_1_end_link"/>
        </joint>
    
        <link name="${name}_1023_1_end_link"/>
    
    
    
    
    
    
    
        <joint name="${name}_a_base_joint" type="fixed">
            <parent link="${name}_1023_1_end_link"/>
            <origin xyz="0 0 0" rpy="0 0 0"/>
            <child link="${name}_1028_base_link"/>
        </joint>
    
        <link name="${name}_1028_base_link">
            <visual>
                <geometry>
                    <mesh filename="package://bpl_bravo_description/meshes/RS2-1028.stl"/>
                </geometry>
                <material name="${name}_black"/>
            </visual>
            <collision>
                <geometry>
                    <cylinder radius="0.0408" length="0.120"/>
                </geometry>
                <origin xyz="0 0 0.06" rpy="0 0 0"/>
            </collision>
    
        </link>
    
    
        <joint name="${name}_1028_end_joint" type="fixed">
            <parent link="${name}_1028_base_link"/>
            <origin xyz="0 0 0.120" rpy="-1.5707 -1.5707 0"/>
            <child link="${name}_1028_end_link"/>
        </joint>
    
        <link name="${name}_1028_end_link"/>
    
    
    
        <joint name="${name}_jaws_joint" type="fixed">
            <origin rpy="0 0 0" xyz=" 0 0 0.0"/>
            <parent link="${name}_1028_end_link"/>
            <child link="${name}_jaws_base_link"/>
        </joint>
    
    
        <link name="${name}_jaws_base_link">
    <!--        <visual>-->
    <!--            <geometry>-->
    <!--                <mesh filename="package://bpl_bravo_description/meshes/end_effectors/RS2-257.stl"/>-->
    <!--            </geometry>-->
    <!--            <material name="bravo_jaws_black"/>-->
    <!--            </visual>-->
        </link>
        <link name="${name}_push_rod"/>
        <joint name="${name}_axis_a" type="prismatic">
            <origin rpy="0 0 0" xyz="0 0 0.009"/>
            <parent link="${name}_jaws_base_link"/>
            <child link="${name}_push_rod"/>
            <axis xyz="0 0 1"/>
            <limit effort="10" lower="0" upper="0.035" velocity="10"/>
        </joint>
    
    
        <link name="${name}_1030_base_link">
            <visual>
                <geometry>
                    <mesh filename="package://bpl_bravo_description/meshes/RS2-1030.stl"/>
                </geometry>
                <material name="${name}_black"/>
            </visual>
            <collision>
                <geometry>
                    <cylinder radius="0.046" length="0.03033333"/>
                </geometry>
                <origin xyz="0 0 0.01516666" rpy="0 0 0"/>
            </collision>

            <collision>
                <geometry>
                    <cylinder radius="0.045" length="0.03033333"/>
                </geometry>
                <origin xyz="0 0 0.0455" rpy="0 0 0"/>
            </collision>

            <collision>
                <geometry>
                    <cylinder radius="0.044" length="0.03033333"/>
                </geometry>
                <origin xyz="0 0 0.075833333" rpy="0 0 0"/>
            </collision>

            <collision>
                <geometry>
                    <cylinder radius="0.043" length="0.03033333"/>
                </geometry>
                <origin xyz="0 0 0.1061666666" rpy="0 0 0"/>
            </collision>

            <collision>
                <geometry>
                    <cylinder radius="0.042" length="0.03033333"/>
                </geometry>
                <origin xyz="0 0 0.1365" rpy="0 0 0"/>
            </collision>
            <collision>
                <geometry>
                    <cylinder radius="0.041" length="0.03033333"/>
                </geometry>
                <origin xyz="0 0 0.1668333" rpy="0 0 0"/>
            </collision>
        </link>
    
        <joint name="${name}_1030_base_joint" type="fixed">
            <parent link="${name}_1013_end_link"/>
            <child link="${name}_1030_base_link"/>
            <origin xyz="0 0 0" rpy="0 0 0"/>
        </joint>

        <xacro:include filename="$(find bpl_bravo_description)/urdf/end_effectors/finger_jaws.urdf.xacro"/>
        <xacro:bravo_finger_jaws parent="${name}_jaws_base_link" name="${name}_finger_jaws" axis_a="${name}_axis_a">
            <origin xyz="0 0 0" rpy="0 0 0"/>
        </xacro:bravo_finger_jaws>
    </xacro:macro>
</robot>