<?xml version="1.0" ?>
<!-- =================================================================================== -->
<!-- |    This document was autogenerated by xacro from bravo_7_example.urdf.xacro     | -->
<!-- |    EDITING THIS FILE BY HAND IS NOT RECOMMENDED                                 | -->
<!-- =================================================================================== -->
<robot name="bravo_7_example">
  <link name="base_link"/>
  <joint name="bravo_joint" type="fixed">
    <origin rpy="0 0 0" xyz="0 0 0"/>
    <parent link="base_link"/>
    <child link="bravo_base_link"/>
    <origin rpy="0 0 0" xyz="0 0 0"/>
  </joint>
  <material name="bravo_black">
    <color rgba="0.3 0.3 0.3 1"/>
  </material>
  <link name="bravo_base_link">
    <visual>
      <geometry>
        <mesh filename="package://bpl_bravo_description_mk2/meshes/1019 A.stl"/>
      </geometry>
      <material name="bravo_black"/>
    </visual>
    <collision>
      <geometry>
        <box size="0.0625 0.1112 0.088"/>
      </geometry>
      <origin rpy="0 0 0" xyz="0.03625 00 0.044"/>
    </collision>
    <collision>
      <geometry>
        <box size="0.050 0.080 0.060"/>
      </geometry>
      <origin rpy="0 0 0" xyz="0.025 -0.04556 0.03"/>
    </collision>
    <collision>
      <geometry>
        <cylinder length="0.0851" radius="0.046"/>
      </geometry>
      <origin rpy="0 0 0" xyz="0.0675 0 0.04255"/>
    </collision>
  </link>
  <joint name="bravo_axis_g" type="continuous">
    <parent link="bravo_base_link"/>
    <origin rpy="0 0 3.14159" xyz="0.0665 0 0.08"/>
    <axis xyz="0 0 -1"/>
    <child link="bravo_1019_end_link"/>
    <!-- <limit effort="0" velocity="0" lower="0.0" upper="6.3" /> -->
  </joint>
  <link name="bravo_1019_end_link">
    <visual>
      <geometry>
        <mesh filename="package://bpl_bravo_description_mk2/meshes/1019 B.stl"/>
      </geometry>
      <origin rpy="0 0 3.14159" xyz="0 0 0"/>
      <material name="bravo_black"/>
    </visual>
  </link>
  <joint name="bravo_f_base_joint" type="fixed">
    <parent link="bravo_1019_end_link"/>
    <origin rpy="0 0 0" xyz="0 0 0.0058"/>
    <child link="bravo_1013_base_link"/>
  </joint>
  <link name="bravo_1013_base_link">
    <visual>
      <geometry>
        <mesh filename="package://bpl_bravo_description_mk2/meshes/1013 A.stl"/>
      </geometry>
      <origin rpy="0 0 3.14159" xyz="0.0 00 0.0"/>
      <material name="bravo_black"/>
    </visual>
    <collision>
      <geometry>
        <cylinder length="0.0667" radius="0.046"/>
      </geometry>
      <origin rpy="0 0 0" xyz="0.0 0.0 0.03335"/>
    </collision>
    <collision>
      <geometry>
        <cylinder length="0.0738" radius="0.046"/>
      </geometry>
      <origin rpy="1.5707 0 0 " xyz="0.046 0.0149 0.0667"/>
    </collision>
  </link>
  <joint name="bravo_axis_f" type="revolute">
    <parent link="bravo_1013_base_link"/>
    <origin rpy="0 0 0" xyz="0.046 0 0.0667"/>
    <axis xyz="0 -1 0"/>
    <child link="bravo_1013_joint_link"/>
    <limit effort="0" lower="0.0" upper="3.2" velocity="0"/>
  </joint>
  <link name="bravo_1013_joint_link">
    <visual>
      <geometry>
        <mesh filename="package://bpl_bravo_description_mk2/meshes/1013 B.stl"/>
      </geometry>
      <material name="bravo_black"/>
      <origin rpy="0 0 3.14159" xyz="0.0 00 0.0"/>
    </visual>
    <collision>
      <geometry>
        <cylinder length="0.0228" radius="0.046"/>
      </geometry>
      <origin rpy="1.5707 0 0 " xyz="0 -0.0334 0"/>
    </collision>
    <collision>
      <geometry>
        <cylinder length="0.05094" radius="0.046"/>
      </geometry>
      <origin rpy="0 0 0" xyz="0.046 0 -0.02547"/>
    </collision>
  </link>
  <joint name="bravo_1013_end_joint" type="fixed">
    <parent link="bravo_1013_joint_link"/>
    <origin rpy="3.14159 0 3.14159" xyz="0.046 0 -0.05334"/>
    <child link="bravo_1013_end_link"/>
  </joint>
  <link name="bravo_1013_end_link"/>
  <joint name="bravo_e_base_joint" type="fixed">
    <parent link="bravo_1013_end_link"/>
    <origin rpy="0 0 0" xyz="0 0 0.182"/>
    <child link="bravo_1026_0_base_link"/>
  </joint>
  <link name="bravo_1026_0_base_link">
    <visual>
      <geometry>
        <mesh filename="package://bpl_bravo_description_mk2/meshes/RS2-1026-A.stl"/>
      </geometry>
      <material name="bravo_black"/>
    </visual>
    <collision>
      <geometry>
        <cylinder length="0.059" radius="0.0408"/>
      </geometry>
      <origin rpy="0 0 0" xyz="0 00 0.0295"/>
    </collision>
    <collision>
      <geometry>
        <cylinder length="0.0599" radius="0.0408"/>
      </geometry>
      <origin rpy="1.5707 0 0" xyz="0.0408 -0.01435 0.059"/>
    </collision>
  </link>
  <joint name="bravo_axis_e" type="revolute">
    <parent link="bravo_1026_0_base_link"/>
    <origin rpy="0 0 0" xyz="0.0408 0 0.059"/>
    <axis xyz="0 -1 0"/>
    <child link="bravo_1026_0_joint_link"/>
    <limit effort="0" lower="0.0" upper="3.2" velocity="0"/>
  </joint>
  <link name="bravo_1026_0_joint_link">
    <visual>
      <geometry>
        <mesh filename="package://bpl_bravo_description_mk2/meshes/RS2-1026-B.stl"/>
      </geometry>
      <material name="bravo_black"/>
    </visual>
    <collision>
      <geometry>
        <cylinder length="0.02335" radius="0.0408"/>
      </geometry>
      <origin rpy="1.5707 0 0" xyz="0 0.027275 0 "/>
    </collision>
    <collision>
      <geometry>
        <cylinder length="0.0851" radius="0.0408"/>
      </geometry>
      <origin rpy="0 0 0" xyz="0.0408 0 -0.0473"/>
    </collision>
  </link>
  <joint name="bravo_1026_0_end_joint" type="fixed">
    <parent link="bravo_1026_0_joint_link"/>
    <origin rpy="3.14159 0 0" xyz="0.0408 0 -0.08705"/>
    <child link="bravo_1026_0_end_link"/>
  </joint>
  <link name="bravo_1026_0_end_link"/>
  <joint name="bravo_d_base_joint" type="fixed">
    <parent link="bravo_1026_0_end_link"/>
    <origin rpy="0 0 0" xyz="0 0 0"/>
    <child link="bravo_1026_1_base_link"/>
  </joint>
  <link name="bravo_1026_1_base_link">
        </link>
  <joint name="bravo_axis_d" type="continuous">
    <parent link="bravo_1026_1_base_link"/>
    <origin rpy="0 0 0" xyz="0 0 0"/>
    <axis xyz="0 0 -1"/>
    <child link="bravo_1026_1_joint_link"/>
    <!-- <limit effort="0" velocity="0" lower="0" upper="6.2" /> -->
  </joint>
  <link name="bravo_1026_1_joint_link">
    <visual>
      <geometry>
        <mesh filename="package://bpl_bravo_description_mk2/meshes/RS2-1026-C.stl"/>
      </geometry>
      <material name="bravo_black"/>
      <origin rpy="0 0 0" xyz="0 0 0 "/>
    </visual>
    <collision>
      <geometry>
        <cylinder length="0.003" radius="0.0408"/>
      </geometry>
      <origin rpy="0 0 3.14159" xyz="0 0 0.000"/>
    </collision>
  </link>
  <joint name="bravo_1026_1_end_joint" type="fixed">
    <parent link="bravo_1026_1_joint_link"/>
    <origin rpy="0 0 3.14159" xyz="0 0 0.0054"/>
    <child link="bravo_1026_1_end_link"/>
  </joint>
  <link name="bravo_1026_1_end_link"/>
  <joint name="bravo_c_base_joint" type="fixed">
    <parent link="bravo_1026_1_end_link"/>
    <origin rpy="0 0 0" xyz="0 0 0.0"/>
    <child link="bravo_1023_0_base_link"/>
  </joint>
  <link name="bravo_1023_0_base_link">
    <visual>
      <geometry>
        <mesh filename="package://bpl_bravo_description_mk2/meshes/RS2-1023-A.stl"/>
      </geometry>
      <material name="bravo_black"/>
    </visual>
    <collision>
      <geometry>
        <cylinder length="0.059" radius="0.0408"/>
      </geometry>
      <origin rpy="0 0 0" xyz="0 00 0.0295"/>
    </collision>
    <collision>
      <geometry>
        <cylinder length="0.0599" radius="0.0408"/>
      </geometry>
      <origin rpy="1.5707 0 0" xyz="0.0408 -0.01435 0.059"/>
    </collision>
  </link>
  <joint name="bravo_axis_c" type="revolute">
    <parent link="bravo_1023_0_base_link"/>
    <origin rpy="0 0 0" xyz="0.0408 0 0.059"/>
    <axis xyz="0 -1 0"/>
    <child link="bravo_1023_0_joint_link"/>
    <limit effort="0" lower="0.0" upper="3.2" velocity="0"/>
  </joint>
  <link name="bravo_1023_0_joint_link">
    <visual>
      <geometry>
        <mesh filename="package://bpl_bravo_description_mk2/meshes/RS2-1023-B.stl"/>
      </geometry>
      <material name="bravo_black"/>
    </visual>
    <collision>
      <geometry>
        <cylinder length="0.02335" radius="0.0408"/>
      </geometry>
      <origin rpy="1.5707 0 0" xyz="0 0.027275 0 "/>
    </collision>
    <collision>
      <geometry>
        <cylinder length="0.0851" radius="0.0408"/>
      </geometry>
      <origin rpy="0 0 0" xyz="0.0408 0 -0.0473"/>
    </collision>
  </link>
  <joint name="bravo_1023_0_end_joint" type="fixed">
    <parent link="bravo_1023_0_joint_link"/>
    <origin rpy="3.14159 0 0" xyz="0.0408 0 -0.08705"/>
    <child link="bravo_1023_0_end_link"/>
  </joint>
  <link name="bravo_1023_0_end_link"/>
  <joint name="bravo_b_base_joint" type="fixed">
    <parent link="bravo_1023_0_end_link"/>
    <origin rpy="0 0 0" xyz="0 0 0"/>
    <child link="bravo_1023_1_base_link"/>
  </joint>
  <link name="bravo_1023_1_base_link">
        </link>
  <joint name="bravo_axis_b" type="continuous">
    <parent link="bravo_1023_1_base_link"/>
    <origin rpy="0 0 3.14159" xyz="0 0 0"/>
    <axis xyz="0 0 -1"/>
    <child link="bravo_1023_1_joint_link"/>
    <!--            <limit effort="0" velocity="0" lower="0.0" upper="0.0" />-->
  </joint>
  <link name="bravo_1023_1_joint_link">
    <visual>
      <geometry>
        <mesh filename="package://bpl_bravo_description_mk2/meshes/RS2-1023-C.stl"/>
      </geometry>
      <material name="bravo_black"/>
    </visual>
    <collision>
      <geometry>
        <cylinder length="0.003" radius="0.0408"/>
      </geometry>
      <origin rpy="0 0 0" xyz="0 0 0.0"/>
    </collision>
  </link>
  <joint name="bravo_1023_1_end_joint" type="fixed">
    <parent link="bravo_1023_1_joint_link"/>
    <origin rpy="0 0 0" xyz="0 0 0.0054"/>
    <child link="bravo_1023_1_end_link"/>
  </joint>
  <link name="bravo_1023_1_end_link"/>
  <joint name="bravo_a_base_joint" type="fixed">
    <parent link="bravo_1023_1_end_link"/>
    <origin rpy="0 0 0" xyz="0 0 0"/>
    <child link="bravo_1038_base_link"/>
  </joint>
  <link name="bravo_1038_base_link">
    <visual>
      <geometry>
        <mesh filename="package://bpl_bravo_description_mk2/meshes/1038.stl"/>
      </geometry>
      <material name="bravo_black"/>
    </visual>
    <collision>
      <geometry>
        <cylinder length="0.12535" radius="0.0408"/>
      </geometry>
      <origin rpy="0 0 0" xyz="0 0 0.06"/>
    </collision>
  </link>
  <joint name="bravo_1038_end_joint" type="fixed">
    <parent link="bravo_1038_base_link"/>
    <origin rpy="0 -1.5707 0" xyz="0 0 0.12535"/>
    <child link="bravo_1038_end_link"/>
  </joint>
  <link name="bravo_1038_end_link"/>
  <joint name="bravo_jaws_joint" type="fixed">
    <origin rpy="0 0 0" xyz=" 0 0 0.0"/>
    <parent link="bravo_1038_end_link"/>
    <child link="bravo_jaws_base_link"/>
  </joint>
  <link name="bravo_jaws_base_link">
    <!--        <visual>-->
    <!--            <geometry>-->
    <!--                <mesh filename="package://bpl_bravo_description/meshes/end_effectors/RS2-257.stl"/>-->
    <!--            </geometry>-->
    <!--            <material name="bravo_jaws_black"/>-->
    <!--            </visual>-->
  </link>
  <link name="bravo_push_rod"/>
  <joint name="bravo_axis_a" type="prismatic">
    <origin rpy="0 0 0" xyz="0 0 0.009"/>
    <parent link="bravo_jaws_base_link"/>
    <child link="bravo_push_rod"/>
    <axis xyz="0 0 1"/>
    <limit effort="10" lower="0" upper="0.01" velocity="10"/>
  </joint>
  <link name="bravo_1030_base_link">
    <visual>
      <geometry>
        <mesh filename="package://bpl_bravo_description_mk2/meshes/1030.stl"/>
      </geometry>
      <material name="bravo_black"/>
    </visual>
    <collision>
      <geometry>
        <cylinder length="0.03033333" radius="0.046"/>
      </geometry>
      <origin rpy="0 0 0" xyz="0 0 0.01516666"/>
    </collision>
    <collision>
      <geometry>
        <cylinder length="0.03033333" radius="0.045"/>
      </geometry>
      <origin rpy="0 0 0" xyz="0 0 0.0455"/>
    </collision>
    <collision>
      <geometry>
        <cylinder length="0.03033333" radius="0.044"/>
      </geometry>
      <origin rpy="0 0 0" xyz="0 0 0.075833333"/>
    </collision>
    <collision>
      <geometry>
        <cylinder length="0.03033333" radius="0.043"/>
      </geometry>
      <origin rpy="0 0 0" xyz="0 0 0.1061666666"/>
    </collision>
    <collision>
      <geometry>
        <cylinder length="0.03033333" radius="0.042"/>
      </geometry>
      <origin rpy="0 0 0" xyz="0 0 0.1365"/>
    </collision>
    <collision>
      <geometry>
        <cylinder length="0.03033333" radius="0.041"/>
      </geometry>
      <origin rpy="0 0 0" xyz="0 0 0.1668333"/>
    </collision>
  </link>
  <joint name="bravo_1030_base_joint" type="fixed">
    <parent link="bravo_1013_end_link"/>
    <child link="bravo_1030_base_link"/>
    <origin rpy="0 0 0" xyz="0 0 0"/>
  </joint>
  <material name="bravo_finger_jaws_black">
    <color rgba="0.3 0.3 0.3 1"/>
  </material>
  <joint name="bravo_finger_jaws_joint" type="fixed">
    <origin rpy="0 0 0" xyz="0 0 0"/>
    <parent link="bravo_jaws_base_link"/>
    <child link="bravo_finger_jaws_base_link"/>
    <origin rpy="0 0 0" xyz="0 0 0"/>
  </joint>
  <link name="bravo_finger_jaws_base_link">
    <visual>
      <geometry>
        <mesh filename="package://bpl_bravo_description_mk2/meshes/RS2-257.stl"/>
      </geometry>
      <material name="bravo_finger_jaws_black"/>
    </visual>
    <collision>
      <geometry>
        <cylinder length="0.037" radius="0.0355"/>
      </geometry>
      <origin rpy="0 1.5707 0" xyz="0.0123 0 0"/>
    </collision>
  </link>
  <link name="bravo_finger_jaws_rs2_300_link">
    <visual>
      <geometry>
        <mesh filename="package://bpl_bravo_description_mk2/meshes/RS2-300.stl"/>
      </geometry>
      <material name="bravo_finger_jaws_black"/>
    </visual>
    <collision>
      <geometry>
        <box size="0.124 0.035 0.042"/>
      </geometry>
      <origin rpy="0 0 2.78554548618295" xyz="0.0595 -0.0267 0"/>
    </collision>
  </link>
  <joint name="bravo_finger_jaws_rs2_300_joint" type="revolute">
    <origin rpy="0 0 0" xyz="0.0241 0.0268 0"/>
    <axis xyz="0 0 1"/>
    <parent link="bravo_finger_jaws_base_link"/>
    <child link="bravo_finger_jaws_rs2_300_link"/>
    <limit effort="10" lower="0" upper="1.0" velocity="10"/>
    <mimic joint="bravo_axis_a" multiplier="54" offset="0"/>
  </joint>
  <link name="bravo_finger_jaws_rs2_301_link">
    <visual>
      <geometry>
        <mesh filename="package://bpl_bravo_description_mk2/meshes/RS2-301.stl"/>
      </geometry>
      <material name="bravo_finger_jaws_black"/>
    </visual>
    <collision>
      <geometry>
        <box size="0.124 0.035 0.042"/>
      </geometry>
      <origin rpy="0 0 -2.78554548618295" xyz="0.0595 0.0267 0"/>
    </collision>
  </link>
  <joint name="bravo_finger_jaws_rs2_301_joint" type="revolute">
    <origin rpy="0 0 0" xyz="0.0241 -0.0268 0"/>
    <axis xyz="0 0 -1"/>
    <parent link="bravo_finger_jaws_base_link"/>
    <child link="bravo_finger_jaws_rs2_301_link"/>
    <limit effort="10" lower="0" upper="1.0" velocity="10"/>
    <mimic joint="bravo_finger_jaws_rs2_300_joint" multiplier="1" offset="0"/>
  </joint>
</robot>

