<?xml version="1.0"?>
<robot name="bravo_finger_jaws" xmlns:xacro="http://ros.org/wiki/xacro">
    <xacro:macro name="bravo_finger_jaws" params="parent *origin name:=bravo_finger_jaws axis_a">
        <material name="${name}_black">
            <color rgba="0.3 0.3 0.3 1" />
        </material>
        <joint name="${name}_joint" type="fixed">
            <xacro:insert_block name="origin" />
            <parent link="${parent}"/>
            <child link="${name}_base_link" />
            <origin xyz="0 0 0" rpy="0 0 0"/>
        </joint>

        <link name="${name}_base_link">
            <visual>
                <geometry>
                    <mesh filename="package://bpl_bravo_description/meshes/end_effectors/RS2-257.stl"/>
                </geometry>
                <material name="${name}_black"/>
            </visual>
            <collision>
                <geometry>
                    <cylinder length="0.02" radius="0.05"/>
                </geometry>
                <origin xyz="0.01 0 0.00" rpy="0 1.5707 0"/>
            </collision>
        </link>

        <link name="${name}_rs2_300_link">
            <visual>
                <geometry>
                    <mesh filename="package://bpl_bravo_description/meshes/end_effectors/RS2-300.stl"/>
                </geometry>
                <material name="${name}_black"/>

            </visual>
            <collision>
                <geometry>
                    <box size="0.14 0.04 0.045"/>
                </geometry>
                <origin xyz="0.07 0.025 0.00" rpy="0 0 0.35"/>
            </collision>
        </link>

        <joint name="${name}_rs2_300_joint" type="revolute">
            <origin xyz="0.0097 -0.033 0" rpy="0 0 0"/>
            <parent link="${name}_base_link"/>
            <child link="${name}_rs2_300_link"/>
            <axis xyz="0 0 -1"/>
            <limit lower="0" upper="1.0" effort="10" velocity="10"/>
            <mimic joint="${axis_a}" multiplier="18" offset="0"/>
        </joint>

        <link name="${name}_rs2_301_link">
            <visual>
                <geometry>
                    <mesh filename="package://bpl_bravo_description/meshes/end_effectors/RS2-301.stl"/>
                </geometry>
                <material name="${name}_black"/>
            </visual>
            <collision>
                <geometry>
                    <box size="0.14 0.04 0.045"/>
                </geometry>
                <origin xyz="0.07 -0.025 0.00" rpy="0 0 -0.35"/>
            </collision>
        </link>

        <joint name="${name}_rs2_301_joint" type="revolute">
            <origin xyz="0.0097 0.033 0" rpy="0 0 0"/>
            <parent link="${name}_base_link"/>
            <child link="${name}_rs2_301_link"/>
            <axis xyz="0 0 1"/>
            <limit lower="0" upper="1.0" effort="10" velocity="10"/>
            <mimic joint="${name}_rs2_300_joint" multiplier="1" offset="0"/>
        </joint>
    </xacro:macro>
</robot>